const test = async () => {
    try {

    }
    catch (e) {
        console.log(e);
        throw new Error('Something went wrong');
    }
};